wandb: Starting wandb agent 🕵️
2025-03-22 22:21:35,640 - wandb.wandb_agent - INFO - Running runs: []
2025-03-22 22:21:35,880 - wandb.wandb_agent - INFO - Agent received command: run
2025-03-22 22:21:35,880 - wandb.wandb_agent - INFO - Agent starting run with config:
	checkpoint.enabled: False
	datapipe.seed: 84
	schedule.phase1.iterations: 200
	schedule.phase1.lr_end: 0.1
	schedule.phase1.lr_start: 0.005
	schedule.phase2.iterations: 200
	schedule.phase2.lr_objective: 0.0001
	schedule.phase3.iterations: 200
	schedule.phase3.lr: 0.0001
	schedule.phase3.rollout_steps_increments: 4
2025-03-22 22:21:35,884 - wandb.wandb_agent - INFO - About to run command: python -m torch.distributed.run --nnodes=1 --nproc_per_node=4 train_graphcast.py checkpoint.enabled=False datapipe.seed=84 schedule.phase1.iterations=200 schedule.phase1.lr_end=0.1 schedule.phase1.lr_start=0.005 schedule.phase2.iterations=200 schedule.phase2.lr_objective=0.0001 schedule.phase3.iterations=200 schedule.phase3.lr=0.0001 schedule.phase3.rollout_steps_increments=4
2025-03-22 22:21:40,892 - wandb.wandb_agent - INFO - Running runs: ['rtrjxd4j']
[2025-03-22 22:22:00,866][main][INFO] - [94mRank: 2, Device: cuda:2[0m
[2025-03-22 22:22:00,866][main][INFO] - [94mRank: 1, Device: cuda:1[0m
[2025-03-22 22:22:00,867][main][INFO] - [94mRank: 3, Device: cuda:3[0m
[2025-03-22 22:22:00,871][main][INFO] - [94mRank: 0, Device: cuda:0[0m
wandb: WARNING Unable to verify login in offline mode.
wandb: WARNING Ignoring project 'DSM500_FPR' when running a sweep.
wandb: WARNING Ignoring entity 'schups' when running a sweep.
wandb: Tracking run with wandb version 0.19.8
wandb: Run data is saved locally in /iopsstor/scratch/cscs/stefschu/DSM500_FPR/modulus-baseline/wandb/wandb/run-20250322_222201-rtrjxd4j
wandb: Run `wandb offline` to turn off syncing.
wandb: Syncing run Baseline_293562_25/03/22_22:22:00_RUN_01
wandb: ⭐️ View project at https://wandb.ai/schups/DSM500_FPR
wandb: 🧹 View sweep at https://wandb.ai/schups/DSM500_FPR/sweeps/mpgn79e1
wandb: 🚀 View run at https://wandb.ai/schups/DSM500_FPR/runs/rtrjxd4j
[2025-03-22 22:22:02,653][trainer][INFO] - [94mSetting seed to 84[0m
[2025-03-22 22:22:02,702][cache][INFO] - [94mLoading cache for 'meshes'.[0m
[2025-03-22 22:22:02,705][cache][INFO] - [94mChecking if 'meshes' is cached.[0m
[2025-03-22 22:22:02,706][cache][INFO] - [94m-> HIT! '/iopsstor/scratch/cscs/stefschu/DSM500_FPR/cache/icosahedron_meshes.pickled' exists.[0m
[2025-03-22 22:22:02,707][cache][INFO] - [94m-> Checking guard 'MeshesCacheGuard'.[0m
[2025-03-22 22:22:07,176][trainer][INFO] - [94mModel created. Trainable parameters count is 35'248'149[0m
Error executing job with overrides: ['checkpoint.enabled=False', 'datapipe.seed=84', 'schedule.phase1.iterations=200', 'schedule.phase1.lr_end=0.1', 'schedule.phase1.lr_start=0.005', 'schedule.phase2.iterations=200', 'schedule.phase2.lr_objective=0.0001', 'schedule.phase3.iterations=200', 'schedule.phase3.lr=0.0001', 'schedule.phase3.rollout_steps_increments=4']
Error executing job with overrides: ['checkpoint.enabled=False', 'datapipe.seed=84', 'schedule.phase1.iterations=200', 'schedule.phase1.lr_end=0.1', 'schedule.phase1.lr_start=0.005', 'schedule.phase2.iterations=200', 'schedule.phase2.lr_objective=0.0001', 'schedule.phase3.iterations=200', 'schedule.phase3.lr=0.0001', 'schedule.phase3.rollout_steps_increments=4']
Error executing job with overrides: ['checkpoint.enabled=False', 'datapipe.seed=84', 'schedule.phase1.iterations=200', 'schedule.phase1.lr_end=0.1', 'schedule.phase1.lr_start=0.005', 'schedule.phase2.iterations=200', 'schedule.phase2.lr_objective=0.0001', 'schedule.phase3.iterations=200', 'schedule.phase3.lr=0.0001', 'schedule.phase3.rollout_steps_increments=4']
Error executing job with overrides: ['checkpoint.enabled=False', 'datapipe.seed=84', 'schedule.phase1.iterations=200', 'schedule.phase1.lr_end=0.1', 'schedule.phase1.lr_start=0.005', 'schedule.phase2.iterations=200', 'schedule.phase2.lr_objective=0.0001', 'schedule.phase3.iterations=200', 'schedule.phase3.lr=0.0001', 'schedule.phase3.rollout_steps_increments=4']
Traceback (most recent call last):
Traceback (most recent call last):
  File "/iopsstor/scratch/cscs/stefschu/DSM500_FPR/modulus-baseline/train_graphcast.py", line 36, in main
    trainer = GraphCastTrainer(cfg)
  File "/iopsstor/scratch/cscs/stefschu/DSM500_FPR/modulus-baseline/train_graphcast.py", line 36, in main
    trainer = GraphCastTrainer(cfg)
  File "/iopsstor/scratch/cscs/stefschu/DSM500_FPR/modulus-baseline/modulus/utils/trainer.py", line 58, in __init__
    self.datapipe_training = self.instantiate_datapipe(
  File "/iopsstor/scratch/cscs/stefschu/DSM500_FPR/modulus-baseline/modulus/utils/trainer.py", line 58, in __init__
    self.datapipe_training = self.instantiate_datapipe(
  File "/iopsstor/scratch/cscs/stefschu/DSM500_FPR/modulus-baseline/modulus/utils/trainer.py", line 155, in instantiate_datapipe
    datapipe = ERA5HDF5Datapipe(
  File "/iopsstor/scratch/cscs/stefschu/DSM500_FPR/modulus-baseline/modulus/utils/trainer.py", line 155, in instantiate_datapipe
    datapipe = ERA5HDF5Datapipe(
TypeError: ERA5HDF5Datapipe.__init__() got an unexpected keyword argument 'shuffle'
TypeError: ERA5HDF5Datapipe.__init__() got an unexpected keyword argument 'shuffle'

Set the environment variable HYDRA_FULL_ERROR=1 for a complete stack trace.

Set the environment variable HYDRA_FULL_ERROR=1 for a complete stack trace.
Traceback (most recent call last):
  File "/iopsstor/scratch/cscs/stefschu/DSM500_FPR/modulus-baseline/train_graphcast.py", line 36, in main
    trainer = GraphCastTrainer(cfg)
  File "/iopsstor/scratch/cscs/stefschu/DSM500_FPR/modulus-baseline/modulus/utils/trainer.py", line 58, in __init__
    self.datapipe_training = self.instantiate_datapipe(
  File "/iopsstor/scratch/cscs/stefschu/DSM500_FPR/modulus-baseline/modulus/utils/trainer.py", line 155, in instantiate_datapipe
    datapipe = ERA5HDF5Datapipe(
TypeError: ERA5HDF5Datapipe.__init__() got an unexpected keyword argument 'shuffle'

Set the environment variable HYDRA_FULL_ERROR=1 for a complete stack trace.
Traceback (most recent call last):
  File "/iopsstor/scratch/cscs/stefschu/DSM500_FPR/modulus-baseline/train_graphcast.py", line 36, in main
    trainer = GraphCastTrainer(cfg)
  File "/iopsstor/scratch/cscs/stefschu/DSM500_FPR/modulus-baseline/modulus/utils/trainer.py", line 58, in __init__
    self.datapipe_training = self.instantiate_datapipe(
  File "/iopsstor/scratch/cscs/stefschu/DSM500_FPR/modulus-baseline/modulus/utils/trainer.py", line 155, in instantiate_datapipe
    datapipe = ERA5HDF5Datapipe(
TypeError: ERA5HDF5Datapipe.__init__() got an unexpected keyword argument 'shuffle'

Set the environment variable HYDRA_FULL_ERROR=1 for a complete stack trace.
W0322 22:22:13.410000 235941 torch/distributed/elastic/multiprocessing/api.py:890] Sending process 235945 closing signal SIGTERM
W0322 22:22:13.412000 235941 torch/distributed/elastic/multiprocessing/api.py:890] Sending process 235946 closing signal SIGTERM
W0322 22:22:13.415000 235941 torch/distributed/elastic/multiprocessing/api.py:890] Sending process 235948 closing signal SIGTERM
E0322 22:22:13.896000 235941 torch/distributed/elastic/multiprocessing/api.py:862] failed (exitcode: 1) local_rank: 2 (pid: 235947) of binary: /iopsstor/scratch/cscs/stefschu/DSM500_FPR/env/venv_arm64/bin/python
Traceback (most recent call last):
  File "/usr/lib/python3.10/runpy.py", line 196, in _run_module_as_main
    return _run_code(code, main_globals, None,
  File "/usr/lib/python3.10/runpy.py", line 86, in _run_code
    exec(code, run_globals)
  File "/usr/local/lib/python3.10/dist-packages/torch/distributed/run.py", line 923, in <module>
    main()
  File "/usr/local/lib/python3.10/dist-packages/torch/distributed/elastic/multiprocessing/errors/__init__.py", line 355, in wrapper
    return f(*args, **kwargs)
  File "/usr/local/lib/python3.10/dist-packages/torch/distributed/run.py", line 919, in main
    run(args)
  File "/usr/local/lib/python3.10/dist-packages/torch/distributed/run.py", line 910, in run
    elastic_launch(
  File "/usr/local/lib/python3.10/dist-packages/torch/distributed/launcher/api.py", line 138, in __call__
    return launch_agent(self._config, self._entrypoint, list(args))
  File "/usr/local/lib/python3.10/dist-packages/torch/distributed/launcher/api.py", line 269, in launch_agent
    raise ChildFailedError(
torch.distributed.elastic.multiprocessing.errors.ChildFailedError: 
============================================================
train_graphcast.py FAILED
------------------------------------------------------------
Failures:
  <NO_OTHER_FAILURES>
------------------------------------------------------------
Root Cause (first observed failure):
[0]:
  time      : 2025-03-22_22:22:13
  host      : nid005019
  rank      : 2 (local_rank: 2)
  exitcode  : 1 (pid: 235947)
  error_file: <N/A>
  traceback : To enable traceback see: https://pytorch.org/docs/stable/elastic/errors.html
============================================================
wandb: - 0.030 MB of 0.030 MB uploaded2025-03-22 22:22:16,870 - wandb.wandb_agent - INFO - Cleaning up finished run: rtrjxd4j
wandb: Terminating and syncing runs. Press ctrl-c to kill.
